<?xml version="1.0" encoding="utf-8"?>
<!-- This URDF was automatically created by SolidWorks to URDF Exporter! Originally created by Stephen Brawner (brawner@gmail.com) 
     Commit Version: 1.5.1-0-g916b5db  Build Version: 1.5.7152.31018
     For more information, please see http://wiki.ros.org/sw_urdf_exporter -->
<robot
  name="rover" xmlns:xacro="http://ros.org/wiki/xacro">
  <gazebo>
    <plugin name="gazebo_ros_control" filename="libgazebo_ros_control.so">
      <robotNamespace>/rover</robotNamespace>
    </plugin>
  </gazebo>
  <link
    name="base_link">
    <inertial>
      <origin
        xyz="-0.225 -1.11022302462516E-16 -0.125"
        rpy="0 0 0" />
      <mass
        value="30.9375" />
      <inertia
        ixx="1.7431640625"
        ixy="-3.78458838342273E-17"
        ixz="-7.7412035115465E-18"
        iyy="1.478203125"
        iyz="9.94729441762504E-34"
        izz="2.5241015625" />
    </inertial>
    <visual>
      <origin
        xyz="0 0 0"
        rpy="0 0 0" />
      <geometry>
        <mesh
          filename="package://rover/meshes/base_link.STL" />
      </geometry>
      <material
        name="">
        <color
          rgba="1 1 1 1" />
      </material>
    </visual>
    <collision>
      <origin
        xyz="0 0 0"
        rpy="0 0 0" />
      <geometry>
        <mesh
          filename="package://rover/meshes/base_link.STL" />
      </geometry>
    </collision>
  </link>

  <link name="body_imu">
    <inertial>
      <origin
        xyz="0 0 0"
        rpy="0 0 0" />
      <mass
        value="0.1" />
      <inertia
        ixx="1E-6"
        ixy="1E-6"
        ixz="1E-6"
        iyy="1E-6"
        iyz="1E-6"
        izz="1E-6" />
    </inertial>
    <visual>
      <origin
        xyz="0 0 0"
        rpy="0 0 0" />
      <geometry>
        <box size="0.05 0.05 0.01"/>
      </geometry>
      <material
        name="">
        <color
          rgba="1 0 1 1" />
      </material>
    </visual>
    <collision>
      <origin
        xyz="0 0 0"
        rpy="0 0 0" />
      <geometry>
        <box size="0.05 0.05 0.01"/>
      </geometry>
    </collision>
  </link>
  <joint
    name="base_to_body_imu"
    type="fixed">
    <origin
      xyz="-0.25 0 0.005"
      rpy="0 0 0" />
    <parent
      link="base_link" />
    <child
      link="body_imu" />
    <axis
      xyz="0 0 0" />
  </joint>

<link name="body_camera">
    <inertial>
      <origin
        xyz="0 0 0"
        rpy="0 0 0" />
      <mass
        value="0.1" />
      <inertia
        ixx="1E-6"
        ixy="1E-6"
        ixz="1E-6"
        iyy="1E-6"
        iyz="1E-6"
        izz="1E-6" />
    </inertial>
    <visual>
      <origin
        xyz="0 0 0"
        rpy="0 0 0" />
      <geometry>
        <box size="0.05 0.05 0.05"/>
      </geometry>
      <material
        name="">
        <color
          rgba="1 0 1 1" />
      </material>
    </visual>
    <collision>
      <origin
        xyz="0 0 0"
        rpy="0 0 0" />
      <geometry>
        <box size="0.05 0.05 0.01"/>
      </geometry>
    </collision>
  </link>
  <joint
    name="base_to_body_camera"
    type="fixed">
    <origin
      xyz="0 0 0.025"
      rpy="0 0.2 0" />
    <parent
      link="base_link" />
    <child
      link="body_camera" />
    <axis
      xyz="0 0 0" />
  </joint>
  <joint name="camera_optical_joint" type="fixed">
    <!-- these values have to be these values otherwise the gazebo camera
        image won't be aligned properly with the frame it is supposedly
        originating from -->
    <origin xyz="0 0 0" rpy="${-pi/2} 0 ${-pi/2}"/>
    <parent link="body_camera"/>
    <child link="camera_link_optical"/>
  </joint>

  <link name="camera_link_optical">
  </link>


<link name="ground_camera">
    <inertial>
      <origin
        xyz="0 0 0"
        rpy="0 0 0" />
      <mass
        value="0.1" />
      <inertia
        ixx="1E-6"
        ixy="1E-6"
        ixz="1E-6"
        iyy="1E-6"
        iyz="1E-6"
        izz="1E-6" />
    </inertial>
    <visual>
      <origin
        xyz="0 0 0"
        rpy="0 0 0" />
      <geometry>
        <box size="0.05 0.05 0.05"/>
      </geometry>
      <material
        name="">
        <color
          rgba="1 0 1 1" />
      </material>
    </visual>
    <collision>
      <origin
        xyz="0 0 0"
        rpy="0 0 0" />
      <geometry>
        <box size="0.05 0.05 0.01"/>
      </geometry>
    </collision>
  </link>
  <joint
    name="base_to_ground_camera"
    type="fixed">
    <origin
      xyz="-0.200 0 -0.275"
      rpy="0 1.5707 0" />
    <parent
      link="base_link" />
    <child
      link="ground_camera" />
    <axis
      xyz="0 0 0" />
  </joint>
  <joint name="ground_camera_optical_joint" type="fixed">
    <!-- these values have to be these values otherwise the gazebo camera
        image won't be aligned properly with the frame it is supposedly
        originating from -->
    <origin xyz="0 0 0" rpy="${-pi/2} 0 ${-pi/2}"/>
    <parent link="ground_camera"/>
    <child link="ground_camera_link_optical"/>
  </joint>

  <link name="ground_camera_link_optical">
  </link>


  <link
    name="left_leg_upper">
    <inertial>
      <origin
        xyz="-0.194165747411793 -0.112389539399822 -0.000731351711592554"
        rpy="0 0 0" />
      <mass
        value="1.93248346185159" />
      <inertia
        ixx="0.0330489550335704"
        ixy="-0.0318954932035645"
        ixz="9.8708775108311E-05"
        iyy="0.126428004084038"
        iyz="0.000159249238895126"
        izz="0.159014173585941" />
    </inertial>
    <visual>
      <origin
        xyz="0 0 0"
        rpy="0 0 0" />
      <geometry>
        <mesh
          filename="package://rover/meshes/left_leg_upper.STL" />
      </geometry>
      <material
        name="">
        <color
          rgba="1 1 1 1" />
      </material>
    </visual>
    <collision>
      <origin
        xyz="0 0 0"
        rpy="0 0 0" />
      <geometry>
        <mesh
          filename="package://rover/meshes/left_leg_upper.STL" />
      </geometry>
    </collision>
  </link>
  <joint
    name="base_to_left_leg_upper"
    type="fixed">
    <origin
      xyz="-0.35 0.27 -0.12"
      rpy="1.5707963267949 0 3.14159265358979" />
    <parent
      link="base_link" />
    <child
      link="left_leg_upper" />
    <axis
      xyz="0 0 0" />
  </joint>
  <link
    name="left_front_wheel">
    <inertial>
      <origin
        xyz="0 0 -0.063051"
        rpy="0 0 0" />
      <mass
        value="1.9382" />
      <inertia
        ixx="0.016737"
        ixy="-4.3368E-18"
        ixz="-4.7847E-18"
        iyy="0.016737"
        iyz="-3.3107E-19"
        izz="0.027927" />
    </inertial>
    <visual>
      <origin
        xyz="0 0 0"
        rpy="0 0 0" />
      <geometry>
        <mesh
          filename="package://rover/meshes/left_front_wheel.STL" />
      </geometry>
      <material
        name="">
        <color
          rgba="0.29804 0.29804 0.29804 1" />
      </material>
    </visual>
    <collision>
      <origin
        xyz="0 0 0"
        rpy="0 0 0" />
      <geometry>
        <mesh
          filename="package://rover/meshes/left_front_wheel.STL" />
      </geometry>
    </collision>
  </link>
  <joint
    name="lf"
    type="continuous">
    <origin
      xyz="-0.55 -0.4 0.03"
      rpy="3.1416 0 -2.7485" />
    <parent
      link="left_leg_upper" />
    <child
      link="left_front_wheel" />
    <axis
      xyz="0 0 1" />
    <limit
      effort="60"
      velocity="20" />
    <dynamics
      damping="0.6"
      friction="1" />
  </joint>
  <link
    name="left_leg_lower">
    <inertial>
      <origin
        xyz="-3.20988925231469E-08 -0.10997054731385 9.21239687645681E-07"
        rpy="0 0 0" />
      <mass
        value="1.1716591412149" />
      <inertia
        ixx="0.00566372324013256"
        ixy="2.07742015864643E-08"
        ixz="-1.93567838383602E-08"
        iyy="0.0308249227849267"
        iyz="-1.50396529209713E-08"
        izz="0.0361793132911607" />
    </inertial>
    <visual>
      <origin
        xyz="0 0 0"
        rpy="0 0 0" />
      <geometry>
        <mesh
          filename="package://rover/meshes/left_leg_lower.STL" />
      </geometry>
      <material
        name="">
        <color
          rgba="1 1 1 1" />
      </material>
    </visual>
    <collision>
      <origin
        xyz="0 0 0"
        rpy="0 0 0" />
      <geometry>
        <mesh
          filename="package://rover/meshes/left_leg_lower.STL" />
      </geometry>
    </collision>
  </link>
  <joint
    name="left_leg_upper_to_lower"
    type="continuous">
    <origin
      xyz="0.2 -0.2 0"
      rpy="0 0 0" />
    <parent
      link="left_leg_upper" />
    <child
      link="left_leg_lower" />
    <axis
      xyz="0 0 1" />
    <limit
      lower="-1"
      upper="1"
      effort="0"
      velocity="0" />
  </joint>
  <link
    name="left_mid_wheel">
    <inertial>
      <origin
        xyz="4.1633E-17 0 -0.063051"
        rpy="0 0 0" />
      <mass
        value="1.9382" />
      <inertia
        ixx="0.016737"
        ixy="-2.6563E-18"
        ixz="-2.7439E-18"
        iyy="0.016737"
        iyz="8.0243E-19"
        izz="0.027927" />
    </inertial>
    <visual>
      <origin
        xyz="0 0 0"
        rpy="0 0 0" />
      <geometry>
        <mesh
          filename="package://rover/meshes/left_mid_wheel.STL" />
      </geometry>
      <material
        name="">
        <color
          rgba="0.29804 0.29804 0.29804 1" />
      </material>
    </visual>
    <collision>
      <origin
        xyz="0 0 0"
        rpy="0 0 0" />
      <geometry>
        <mesh
          filename="package://rover/meshes/left_mid_wheel.STL" />
      </geometry>
    </collision>
  </link>
  <joint
    name="lm"
    type="continuous">
    <origin
      xyz="-0.25 -0.2 0.03"
      rpy="3.1416 0 -1.6099" />
    <parent
      link="left_leg_lower" />
    <child
      link="left_mid_wheel" />
    <axis
      xyz="0 0 1" />
    <limit
      effort="60"
      velocity="20" />
    <dynamics
      damping="0.6"
      friction="1" />
  </joint>
  <link
    name="left_back_wheel">
    <inertial>
      <origin
        xyz="0 0 -0.063051"
        rpy="0 0 0" />
      <mass
        value="1.9382" />
      <inertia
        ixx="0.016737"
        ixy="-2.6021E-18"
        ixz="-8.0184E-18"
        iyy="0.016737"
        iyz="-3.2234E-19"
        izz="0.027927" />
    </inertial>
    <visual>
      <origin
        xyz="0 0 0"
        rpy="0 0 0" />
      <geometry>
        <mesh
          filename="package://rover/meshes/left_back_wheel.STL" />
      </geometry>
      <material
        name="">
        <color
          rgba="0.29804 0.29804 0.29804 1" />
      </material>
    </visual>
    <collision>
      <origin
        xyz="0 0 0"
        rpy="0 0 0" />
      <geometry>
        <mesh
          filename="package://rover/meshes/left_back_wheel.STL" />
      </geometry>
    </collision>
  </link>
  <joint
    name="lb"
    type="continuous">
    <origin
      xyz="0.25 -0.2 0.0299999999999998"
      rpy="3.14159265358979 0 -2.74849784316328" />
    <parent
      link="left_leg_lower" />
    <child
      link="left_back_wheel" />
    <axis
      xyz="0 0 1" />
    <limit
      effort="60"
      velocity="20" />
    <dynamics
      damping="0.6"
      friction="1" />
  </joint>
  <link
    name="right_leg_upper">
    <inertial>
      <origin
        xyz="0 0 0"
        rpy="0 0 0" />
      <mass
        value="1.93248346185159" />
      <inertia
        ixx="0.0330489550335704"
        ixy="-0.0318954932035645"
        ixz="9.8708775108311E-05"
        iyy="0.126428004084038"
        iyz="0.000159249238895126"
        izz="0.159014173585941" />
    </inertial>
    <visual>
      <origin
        xyz="0 0 0"
        rpy="0 0 0" />
      <geometry>
        <mesh
          filename="package://rover/meshes/right_leg_upper.STL" />
      </geometry>
      <material
        name="">
        <color
          rgba="1 1 1 1" />
      </material>
    </visual>
    <collision>
      <origin
        xyz="0 0 0"
        rpy="0 0 0" />
      <geometry>
        <mesh
          filename="package://rover/meshes/right_leg_upper.STL" />
      </geometry>
    </collision>
  </link>
  <joint
    name="base_to_right_leg_upper"
    type="fixed">
    <origin
      xyz="-0.35 -0.27 -0.12"
      rpy="1.5707963267949 0 3.14159265358979" />
    <parent
      link="base_link" />
    <child
      link="right_leg_upper" />
    <axis
      xyz="0 0 0" />
  </joint>
  <link
    name="right_front_wheel">
    <inertial>
      <origin
        xyz="-1.1102E-16 -8.3267E-17 -0.063051"
        rpy="0 0 0" />
      <mass
        value="1.9382" />
      <inertia
        ixx="0.016737"
        ixy="3.8392E-18"
        ixz="-1.3175E-18"
        iyy="0.016737"
        iyz="3.5572E-19"
        izz="0.027927" />
    </inertial>
    <visual>
      <origin
        xyz="0 0 0"
        rpy="0 0 0" />
      <geometry>
        <mesh
          filename="package://rover/meshes/right_front_wheel.STL" />
      </geometry>
      <material
        name="">
        <color
          rgba="0.29804 0.29804 0.29804 1" />
      </material>
    </visual>
    <collision>
      <origin
        xyz="0 0 0"
        rpy="0 0 0" />
      <geometry>
        <mesh
          filename="package://rover/meshes/right_front_wheel.STL" />
      </geometry>
    </collision>
  </link>
  <joint
    name="rf"
    type="continuous">
    <origin
      xyz="-0.55 -0.4 -0.0299999999999999"
      rpy="0 0 0" />
    <parent
      link="right_leg_upper" />
    <child
      link="right_front_wheel" />
    <axis
      xyz="0 0 1" />
    <limit
      effort="60"
      velocity="20" />
    <dynamics
      damping="0.6"
      friction="1" />
  </joint>
  <link
    name="right_leg_lower">
    <inertial>
      <origin
        xyz="-3.20988916349685E-08 -0.10997054731385 9.21239687534658E-07"
        rpy="0 0 0" />
      <mass
        value="1.1716591412149" />
      <inertia
        ixx="0.00566372324013256"
        ixy="2.07742015892293E-08"
        ixz="-1.93567838275014E-08"
        iyy="0.0308249227849267"
        iyz="-1.50396529213661E-08"
        izz="0.0361793132911607" />
    </inertial>
    <visual>
      <origin
        xyz="0 0 0"
        rpy="0 0 0" />
      <geometry>
        <mesh
          filename="package://rover/meshes/right_leg_lower.STL" />
      </geometry>
      <material
        name="">
        <color
          rgba="1 1 1 1" />
      </material>
    </visual>
    <collision>
      <origin
        xyz="0 0 0"
        rpy="0 0 0" />
      <geometry>
        <mesh
          filename="package://rover/meshes/right_leg_lower.STL" />
      </geometry>
    </collision>
  </link>
  <joint
    name="right_leg_upper_to_lower"
    type="continuous">
    <origin
      xyz="0.2 -0.2 0"
      rpy="0 0 0" />
    <parent
      link="right_leg_upper" />
    <child
      link="right_leg_lower" />
    <axis
      xyz="0 0 1" />
    <limit
      lower="-1"
      upper="1"
      effort="0"
      velocity="0" />
  </joint>
  <link
    name="right_mid_wheel">
    <inertial>
      <origin
        xyz="5.5511E-17 -1.3878E-17 -0.063051"
        rpy="0 0 0" />
      <mass
        value="1.9382" />
      <inertia
        ixx="0.016737"
        ixy="3.3352E-18"
        ixz="-7.5184E-18"
        iyy="0.016737"
        iyz="3.6161E-19"
        izz="0.027927" />
    </inertial>
    <visual>
      <origin
        xyz="0 0 0"
        rpy="0 0 0" />
      <geometry>
        <mesh
          filename="package://rover/meshes/right_mid_wheel.STL" />
      </geometry>
      <material
        name="">
        <color
          rgba="0.29804 0.29804 0.29804 1" />
      </material>
    </visual>
    <collision>
      <origin
        xyz="0 0 0"
        rpy="0 0 0" />
      <geometry>
        <mesh
          filename="package://rover/meshes/right_mid_wheel.STL" />
      </geometry>
    </collision>
  </link>
  <joint
    name="rm"
    type="continuous">
    <origin
      xyz="-0.25 -0.2 -0.03"
      rpy="0 0 0" />
    <parent
      link="right_leg_lower" />
    <child
      link="right_mid_wheel" />
    <axis
      xyz="0 0 1" />
    <limit
      effort="60"
      velocity="20" />
    <dynamics
      damping="0.6"
      friction="1" />
  </joint>
  <link
    name="right_back_wheel">
    <inertial>
      <origin
        xyz="-1.1102E-16 6.9389E-17 -0.063051"
        rpy="0 0 0" />
      <mass
        value="1.9382" />
      <inertia
        ixx="0.016737"
        ixy="3.0358E-18"
        ixz="-1.3146E-18"
        iyy="0.016737"
        iyz="3.1595E-19"
        izz="0.027927" />
    </inertial>
    <visual>
      <origin
        xyz="0 0 0"
        rpy="0 0 0" />
      <geometry>
        <mesh
          filename="package://rover/meshes/right_back_wheel.STL" />
      </geometry>
      <material
        name="">
        <color
          rgba="0.29804 0.29804 0.29804 1" />
      </material>
    </visual>
    <collision>
      <origin
        xyz="0 0 0"
        rpy="0 0 0" />
      <geometry>
        <mesh
          filename="package://rover/meshes/right_back_wheel.STL" />
      </geometry>
    </collision>
  </link>
  <joint
    name="rb"
    type="continuous">
    <origin
      xyz="0.25 -0.2 -0.03"
      rpy="0 0 -0.0404094746761278" />
    <parent
      link="right_leg_lower" />
    <child
      link="right_back_wheel" />
    <axis
      xyz="0 0 1" />
    <limit
      effort="60"
      velocity="20" />
    <dynamics
      damping="0.6"
      friction="1" />
  </joint>
    <transmission name="lf_trans">
      <type>transmission_interface/SimpleTransmission</type>
      <actuator name="lf_motor">
        <mechanicalReduction>1</mechanicalReduction>
      </actuator>
      <joint name="lf">
	      <hardwareInterface>hardware_interface/EffortJointInterface</hardwareInterface>
      </joint>
    </transmission>

    <transmission name="lm_trans">
      <type>transmission_interface/SimpleTransmission</type>
      <actuator name="lm_motor">
        <mechanicalReduction>1</mechanicalReduction>
      </actuator>
      <joint name="lm">
	      <hardwareInterface>hardware_interface/EffortJointInterface</hardwareInterface>
      </joint>
    </transmission>

    <transmission name="lb_trans">
      <type>transmission_interface/SimpleTransmission</type>
      <actuator name="lb_motor">
        <mechanicalReduction>1</mechanicalReduction>
      </actuator>
      <joint name="lb">
	      <hardwareInterface>hardware_interface/EffortJointInterface</hardwareInterface>
      </joint>
    </transmission>

    <transmission name="rf_trans">
      <type>transmission_interface/SimpleTransmission</type>
      <actuator name="rf_motor">
        <mechanicalReduction>1</mechanicalReduction>
      </actuator>
      <joint name="rf">
	      <hardwareInterface>hardware_interface/EffortJointInterface</hardwareInterface>
      </joint>
    </transmission>

    <transmission name="rm_trans">
      <type>transmission_interface/SimpleTransmission</type>
      <actuator name="rm_motor">
        <mechanicalReduction>1</mechanicalReduction>
      </actuator>
      <joint name="rm">
	      <hardwareInterface>hardware_interface/EffortJointInterface</hardwareInterface>
      </joint>
    </transmission>

    <transmission name="rb_trans">
      <type>transmission_interface/SimpleTransmission</type>
      <actuator name="rb_motor">
        <mechanicalReduction>1</mechanicalReduction>
      </actuator>
      <joint name="rb">
	      <hardwareInterface>hardware_interface/EffortJointInterface</hardwareInterface>
      </joint>
    </transmission>

  <gazebo reference="body_imu">
    <gravity>true</gravity>
    <sensor name="body_imu" type="imu">
      <always_on>true</always_on>
      <update_rate>100</update_rate>
      <visualize>true</visualize>
      <topic>__default_topic__</topic>
      <plugin filename="libgazebo_ros_imu_sensor.so" name="imu_plugin">
        <topicName>/rover/imu</topicName>
        <bodyName>imu_link</bodyName>
        <updateRateHZ>100.0</updateRateHZ>
        <gaussianNoise>0.0</gaussianNoise>
        <xyzOffset>0 0 0</xyzOffset>
        <rpyOffset>0 0 0</rpyOffset>
        <frameName>body_imu</frameName>
      </plugin>
      <pose>0 0 0 0 0 0</pose>
    </sensor>
  </gazebo>
    
<!-- camera -->
  <gazebo reference="ground_camera">
    <sensor type="camera" name="camera1">
      <update_rate>30.0</update_rate>
      <camera name="head">
        <horizontal_fov>1.5707</horizontal_fov>
        <image>
          <width>1280</width>
          <height>720</height>
          <format>R8G8B8</format>
        </image>
        <clip>
          <near>0.02</near>
          <far>300</far>
        </clip>
        <noise>
          <type>gaussian</type>
          <!-- Noise is sampled independently per pixel on each frame.
               That pixel's noise value is added to each of its color
               channels, which at that point lie in the range [0,1]. -->
          <mean>0.0</mean>
          <stddev>0.007</stddev>
        </noise>
      </camera>
      <plugin name="camera_controller" filename="libgazebo_ros_camera.so">
        <alwaysOn>true</alwaysOn>
        <updateRate>0.0</updateRate>
        <cameraName>rover/ground_camera</cameraName>
        <imageTopicName>image_raw</imageTopicName>
        <cameraInfoTopicName>camera_info</cameraInfoTopicName>
        <frameName>ground_camera_link_optical</frameName>
        <hackBaseline>0.07</hackBaseline>
        <distortionK1>0.0</distortionK1>
        <distortionK2>0.0</distortionK2>
        <distortionK3>0.0</distortionK3>
        <distortionT1>0.0</distortionT1>
        <distortionT2>0.0</distortionT2>
      </plugin>
    </sensor>
  </gazebo>

<gazebo reference="body_camera">
  <sensor name="body_camera" type="depth">
    <update_rate>30</update_rate>
    <camera>
      <horizontal_fov>1.5707963</horizontal_fov>
      <image>
        <width>1920</width>
        <height>1080</height>
        <format>R8G8B8</format>
      </image>
      <clip>
        <near>0.3</near>
        <far>25</far>
      </clip>
    </camera>
    <plugin name="body_camera_controller" filename="libgazebo_ros_openni_kinect.so">
      <baseline>0.2</baseline>
      <alwaysOn>true</alwaysOn>
      <updateRate>1.0</updateRate>
      <cameraName>body_camera_ir</cameraName>
      <imageTopicName>/rover/body_camera/color/image_raw</imageTopicName>
      <cameraInfoTopicName>/rover/body_camera/depth/camera_info</cameraInfoTopicName>
      <depthImageTopicName>/rover/body_camera/depth/image_raw</depthImageTopicName>
      <depthImageInfoTopicName>/rover/body_camera/depth/camera_info</depthImageInfoTopicName>
      <pointCloudTopicName>/rover/body_camera/depth/points</pointCloudTopicName>
      <frameName>camera_link_optical</frameName>
      <pointCloudCutoff>0.3</pointCloudCutoff>
      <pointCloudCutoffMax>25.0</pointCloudCutoffMax>
      <distortionK1>0.00000001</distortionK1>
      <distortionK2>0.00000001</distortionK2>
      <distortionK3>0.00000001</distortionK3>
      <distortionT1>0.00000001</distortionT1>
      <distortionT2>0.00000001</distortionT2>
      <CxPrime>0</CxPrime>
      <Cx>0</Cx>
      <Cy>0</Cy>
      <focalLength>0</focalLength>
      <hackBaseline>0</hackBaseline>
    </plugin>
  </sensor>
</gazebo>

<gazebo>
    <plugin name="novatel_gps_sim" filename="libhector_gazebo_ros_gps.so">
      <alwaysOn>1</alwaysOn>
      <updateRate>10.0</updateRate>
      <bodyName>base_link</bodyName>
      <topicName>rover/gps</topicName>
      <velocityTopicName>rover/gps_velocity</velocityTopicName>
      <drift>5.0 5.0 5.0</drift>
      <gaussianNoise>0.1 0.1 0.1</gaussianNoise>
      <velocityDrift>0 0 0</velocityDrift>
      <velocityGaussianNoise>0.1 0.1 0.1</velocityGaussianNoise>
    </plugin>
  </gazebo>

<xacro:macro name="wheel_fric_setting" params="prefix suffix">
<gazebo reference="${prefix}_${suffix}_wheel">
        <mu1>0.45</mu1>
        <mu2>0.40</mu2>
	<material>Gazebo/Grey</material>
</gazebo>
</xacro:macro>

<xacro:wheel_fric_setting prefix="left" suffix="front"/>
<xacro:wheel_fric_setting prefix="left" suffix="mid"/>
<xacro:wheel_fric_setting prefix="left" suffix="back"/>
<xacro:wheel_fric_setting prefix="right" suffix="front"/>
<xacro:wheel_fric_setting prefix="right" suffix="mid"/>
<xacro:wheel_fric_setting prefix="right" suffix="back"/>

</robot>
